2022-01-02T20:37:35.280 daemon chia.daemon.server         : INFO     Starting Daemon Server
2022-01-02T20:37:35.281 daemon chia.daemon.server         : INFO     Waiting Daemon WebSocketServer closure
2022-01-02T20:37:38.730 full_node chia.full_node.full_node: INFO     Initializing blockchain from disk
2022-01-02T20:37:38.731 full_node chia.consensus.blockchain: INFO     Started 14 processes for block validation
2022-01-02T20:37:40.202 full_node full_node               : INFO     got signal 2
2022-01-02T20:37:40.202 full_node full_node               : INFO     Cancelling reconnect task
2022-01-02T20:37:40.202 full_node full_node               : INFO     Closing connections
2022-01-02T20:37:40.202 daemon chia.daemon.server         : INFO     sending term signal to chia_full_node
2022-01-02T20:37:40.203 full_node full_node               : INFO     got signal 15
2022-01-02T20:37:40.203 full_node asyncio                 : ERROR    Task exception was never retrieved
future: <Task finished name='Task-5' coro=<FullNodePeers.close() done, defined at /home/chia/chia-blockchain/chia/server/node_discovery.py:534> exception=AttributeError("'FullNodePeers' object has no attribute 'connection'")>
Traceback (most recent call last):
  File "/home/chia/chia-blockchain/chia/server/node_discovery.py", line 535, in close
    await self._close_common()
  File "/home/chia/chia-blockchain/chia/server/node_discovery.py", line 120, in _close_common
    await self.connection.close()
AttributeError: 'FullNodePeers' object has no attribute 'connection'
2022-01-02T20:37:55.220 daemon chia.daemon.server         : INFO     sending kill signal to chia_full_node
2022-01-02T20:37:55.251 daemon chia.daemon.server         : INFO     process chia_full_node returned -9
2022-01-02T20:37:55.251 daemon chia.daemon.server         : INFO     chia daemon exiting in 5 seconds
2022-01-02T20:37:55.251 daemon chia.daemon.server         : INFO     Daemon WebSocketServer closed
